Workbook

Sheet Aceite
A1: Terminacion | B1: Pozo | C1: Yacimiento | D1: ID | E1: Fecha Muestreo | F1: Fecha Análisis | G1: Densidad | H1: API | I1: Salinidad | J1: pH
A2: {=IFERROR(_xlfn.XLOOKUP(1,(Hoja1!$B$5:$B$1097=B2)*(Hoja1!$E$5:$E$1097=_xlfn.MAXIFS(Hoja1!$E$5:$E$1097,Hoja1!$B$5:$B$1097,B2,Hoja1!$E$5:$E$1097,"<="&E2)),Hoja1!$C$5:$C$1097,""),"")} | B2: =IF(LEFT(D2,1)="T","T-","C-")&TRIM(RIGHT(D2,LEN(D2)-SEARCH("-",D2))) -> C-338 | C2: =IFERROR(MID(A2,FIND("_",A2,FIND("_",A2)+1)+1,LEN(A2)),"") | D2: Constituciones-338 | E2: - | F2: 36630
A3: {=IFERROR(_xlfn.XLOOKUP(1,(Hoja1!$B$5:$B$1097=B3)*(Hoja1!$E$5:$E$1097=_xlfn.MAXIFS(Hoja1!$E$5:$E$1097,Hoja1!$B$5:$B$1097,B3,Hoja1!$E$5:$E$1097,"<="&E3)),Hoja1!$C$5:$C$1097,""),"")} -> TMLP_117D_KTS | B3: =IF(LEFT(D3,1)="T","T-","C-")&TRIM(RIGHT(D3,LEN(D3)-SEARCH("-",D3))) -> T-117D | C3: =IFERROR(MID(A3,FIND("_",A3,FIND("_",A3)+1)+1,LEN(A3)),"") -> KTS | D3: Tamaulipas-117D | E3: 38384 | F3: 38390 | G3: 0.951 | H3: 17.29 | I3: 24778.157 | J3: 8
A4: {=IFERROR(_xlfn.XLOOKUP(1,(Hoja1!$B$5:$B$1097=B4)*(Hoja1!$E$5:$E$1097=_xlfn.MAXIFS(Hoja1!$E$5:$E$1097,Hoja1!$B$5:$B$1097,B4,Hoja1!$E$5:$E$1097,"<="&E4)),Hoja1!$C$5:$C$1097,""),"")} -> TMLP_69D_KTIA | B4: =IF(LEFT(D4,1)="T","T-","C-")&TRIM(RIGHT(D4,LEN(D4)-SEARCH("-",D4))) -> T-69D | C4: =IFERROR(MID(A4,FIND("_",A4,FIND("_",A4)+1)+1,LEN(A4)),"") -> KTIA | D4: Tamaulipas-69D | E4: 38384 | F4: 38390 | G4: 0.9654 | H4: 15.07 | I4: 24851.925 | J4: 8
A5: {=IFERROR(_xlfn.XLOOKUP(1,(Hoja1!$B$5:$B$1097=B5)*(Hoja1!$E$5:$E$1097=_xlfn.MAXIFS(Hoja1!$E$5:$E$1097,Hoja1!$B$5:$B$1097,B5,Hoja1!$E$5:$E$1097,"<="&E5)),Hoja1!$C$5:$C$1097,""),"")} -> TMLP_137_KTIA | B5: =IF(LEFT(D5,1)="T","T-","C-")&TRIM(RIGHT(D5,LEN(D5)-SEARCH("-",D5))) -> T-137 | C5: =IFERROR(MID(A5,FIND("_",A5,FIND("_",A5)+1)+1,LEN(A5)),"") -> KTIA | D5: Tamaulipas-137 | E5: 38384 | F5: 38391 | G5: 0.965 | H5: 15.13 | I5: 56344 | J5: 8
A6: {=IFERROR(_xlfn.XLOOKUP(1,(Hoja1!$B$5:$B$1097=B6)*(Hoja1!$E$5:$E$1097=_xlfn.MAXIFS(Hoja1!$E$5:$E$1097,Hoja1!$B$5:$B$1097,B6,Hoja1!$E$5:$E$1097,"<="&E6)),Hoja1!$C$5:$C$1097,""),"")} -> TMLP_140D_KTIA | B6: =IF(LEFT(D6,1)="T","T-","C-")&TRIM(RIGHT(D6,LEN(D6)-SEARCH("-",D6))) -> T-140D | C6: =IFERROR(MID(A6,FIND("_",A6,FIND("_",A6)+1)+1,LEN(A6)),"") -> KTIA | D6: Tamaulipas-140D | E6: 38384 | F6: 38391 | G6: 0.9545 | H6: 16.75 | I6: 41175 | J6: 8
A7: {=IFERROR(_xlfn.XLOOKUP(1,(Hoja1!$B$5:$B$1097=B7)*(Hoja1!$E$5:$E$1097=_xlfn.MAXIFS(Hoja1!$E$5:$E$1097,Hoja1!$B$5:$B$1097,B7,Hoja1!$E$5:$E$1097,"<="&E7)),Hoja1!$C$5:$C$1097,""),"")} | B7: =IF(LEFT(D7,1)="T","T-","C-")&TRIM(RIGHT(D7,LEN(D7)-SEARCH("-",D7))) -> T-140D | C7: =IFERROR(MID(A7,FIND("_",A7,FIND("_",A7)+1)+1,LEN(A7)),"") | D7: Tamaulipas-140D | F7: 38399 | G7: 0.9463 | H7: 18.03
A8: {=IFERROR(_xlfn.XLOOKUP(1,(Hoja1!$B$5:$B$1097=B8)*(Hoja1!$E$5:$E$1097=_xlfn.MAXIFS(Hoja1!$E$5:$E$1097,Hoja1!$B$5:$B$1097,B8,Hoja1!$E$5:$E$1097,"<="&E8)),Hoja1!$C$5:$C$1097,""),"")} | B8: =IF(LEFT(D8,1)="T","T-","C-")&TRIM(RIGHT(D8,LEN(D8)-SEARCH("-",D8))) -> C-163 | C8: =IFERROR(MID(A8,FIND("_",A8,FIND("_",A8)+1)+1,LEN(A8)),"") | D8: Constituciones-163 | F8: 38414 | G8: 0.976 | H8: 13.49 | I8: 26313 | J8: 8
A9: {=IFERROR(_xlfn.XLOOKUP(1,(Hoja1!$B$5:$B$1097=B9)*(Hoja1!$E$5:$E$1097=_xlfn.MAXIFS(Hoja1!$E$5:$E$1097,Hoja1!$B$5:$B$1097,B9,Hoja1!$E$5:$E$1097,"<="&E9)),Hoja1!$C$5:$C$1097,""),"")} | B9: =IF(LEFT(D9,1)="T","T-","C-")&TRIM(RIGHT(D9,LEN(D9)-SEARCH("-",D9))) -> T-734 | C9: =IFERROR(MID(A9,FIND("_",A9,FIND("_",A9)+1)+1,LEN(A9)),"") | D9: Tamaulipas-734 | F9: 38566 | G9: 0.9634 | H9: 15.38 | I9: 104871 | J9: 6
A10: {=IFERROR(_xlfn.XLOOKUP(1,(Hoja1!$B$5:$B$1097=B10)*(Hoja1!$E$5:$E$1097=_xlfn.MAXIFS(Hoja1!$E$5:$E$1097,Hoja1!$B$5:$B$1097,B10,Hoja1!$E$5:$E$1097,"<="&E10)),Hoja1!$C$5:$C$1097,""),"")} -> CONST_232D_KTS | B10: =IF(LEFT(D10,1)="T","T-","C-")&TRIM(RIGHT(D10,LEN(D10)-SEARCH("-",D10))) -> C-232D | C10: =IFERROR(MID(A10,FIND("_",A10,FIND("_",A10)+1)+1,LEN(A10)),"") -> KTS | D10: Constituciones-232D | E10: 38588 | F10: 38589 | G10: 0.9473 | H10: 17.87 | I10: 12898 | J10: 7.5
A11: {=IFERROR(_xlfn.XLOOKUP(1,(Hoja1!$B$5:$B$1097=B11)*(Hoja1!$E$5:$E$1097=_xlfn.MAXIFS(Hoja1!$E$5:$E$1097,Hoja1!$B$5:$B$1097,B11,Hoja1!$E$5:$E$1097,"<="&E11)),Hoja1!$C$5:$C$1097,""),"")} -> CONST_221_JSA | B11: =IF(LEFT(D11,1)="T","T-","C-")&TRIM(RIGHT(D11,LEN(D11)-SEARCH("-",D11))) -> C-221 | C11: =IFERROR(MID(A11,FIND("_",A11,FIND("_",A11)+1)+1,LEN(A11)),"") -> JSA | D11: Constituciones-221 | E11: 38588 | F11: 38592 | I11: 11063 | J11: 7
A12: {=IFERROR(_xlfn.XLOOKUP(1,(Hoja1!$B$5:$B$1097=B12)*(Hoja1!$E$5:$E$1097=_xlfn.MAXIFS(Hoja1!$E$5:$E$1097,Hoja1!$B$5:$B$1097,B12,Hoja1!$E$5:$E$1097,"<="&E12)),Hoja1!$C$5:$C$1097,""),"")} -> CONST_556_JSA | B12: =IF(LEFT(D12,1)="T","T-","C-")&TRIM(RIGHT(D12,LEN(D12)-SEARCH("-",D12))) -> C-556 | C12: =IFERROR(MID(A12,FIND("_",A12,FIND("_",A12)+1)+1,LEN(A12)),"") -> JSA | D12: Constituciones-556 | E12: 38588 | F12: 38594 | G12: 0.9685 | H12: 14.62 | I12: 24989 | J12: 8
A13: {=IFERROR(_xlfn.XLOOKUP(1,(Hoja1!$B$5:$B$1097=B13)*(Hoja1!$E$5:$E$1097=_xlfn.MAXIFS(Hoja1!$E$5:$E$1097,Hoja1!$B$5:$B$1097,B13,Hoja1!$E$5:$E$1097,"<="&E13)),Hoja1!$C$5:$C$1097,""),"")} -> CONST_202D_KTIA | B13: =IF(LEFT(D13,1)="T","T-","C-")&TRIM(RIGHT(D13,LEN(D13)-SEARCH("-",D13))) -> C-202D | C13: =IFERROR(MID(A13,FIND("_",A13,FIND("_",A13)+1)+1,LEN(A13)),"") -> KTIA | D13: Constituciones-202D | E13: 38588 | F13: 38594 | G13: 0.9513 | H13: 17.26 | I13: 35747 | J13: 7.5
A14: {=IFERROR(_xlfn.XLOOKUP(1,(Hoja1!$B$5:$B$1097=B14)*(Hoja1!$E$5:$E$1097=_xlfn.MAXIFS(Hoja1!$E$5:$E$1097,Hoja1!$B$5:$B$1097,B14,Hoja1!$E$5:$E$1097,"<="&E14)),Hoja1!$C$5:$C$1097,""),"")} -> CONST_232T_KTIA | B14: =IF(LEFT(D14,1)="T","T-","C-")&TRIM(RIGHT(D14,LEN(D14)-SEARCH("-",D14))) -> C-232T | C14: =IFERROR(MID(A14,FIND("_",A14,FIND("_",A14)+1)+1,LEN(A14)),"") -> KTIA | D14: Constituciones-232T | E14: 38588 | F14: 38594 | G14: 0.9473 | H14: 17.87 | I14: 25103 | J14: 7.5
A15: {=IFERROR(_xlfn.XLOOKUP(1,(Hoja1!$B$5:$B$1097=B15)*(Hoja1!$E$5:$E$1097=_xlfn.MAXIFS(Hoja1!$E$5:$E$1097,Hoja1!$B$5:$B$1097,B15,Hoja1!$E$5:$E$1097,"<="&E15)),Hoja1!$C$5:$C$1097,""),"")} -> CONST_572_KTIA | B15: =IF(LEFT(D15,1)="T","T-","C-")&TRIM(RIGHT(D15,LEN(D15)-SEARCH("-",D15))) -> C-572 | C15: =IFERROR(MID(A15,FIND("_",A15,FIND("_",A15)+1)+1,LEN(A15)),"") -> KTIA | D15: Constituciones-572 | E15: 38588 | F15: 38594 | G15: 0.9764 | H15: 13.42 | I15: 27641 | J15: 7.5
A16: {=IFERROR(_xlfn.XLOOKUP(1,(Hoja1!$B$5:$B$1097=B16)*(Hoja1!$E$5:$E$1097=_xlfn.MAXIFS(Hoja1!$E$5:$E$1097,Hoja1!$B$5:$B$1097,B16,Hoja1!$E$5:$E$1097,"<="&E16)),Hoja1!$C$5:$C$1097,""),"")} -> CONST_574_JSA | B16: =IF(LEFT(D16,1)="T","T-","C-")&TRIM(RIGHT(D16,LEN(D16)-SEARCH("-",D16))) -> C-574 | C16: =IFERROR(MID(A16,FIND("_",A16,FIND("_",A16)+1)+1,LEN(A16)),"") -> JSA | D16: Constituciones-574 | E16: 38588 | F16: 38594 | G16: 0.9729 | H16: 13.94 | I16: 28736 | J16: 7.5
A17: {=IFERROR(_xlfn.XLOOKUP(1,(Hoja1!$B$5:$B$1097=B17)*(Hoja1!$E$5:$E$1097=_xlfn.MAXIFS(Hoja1!$E$5:$E$1097,Hoja1!$B$5:$B$1097,B17,Hoja1!$E$5:$E$1097,"<="&E17)),Hoja1!$C$5:$C$1097,""),"")} -> CONST_119_JSA | B17: =IF(LEFT(D17,1)="T","T-","C-")&TRIM(RIGHT(D17,LEN(D17)-SEARCH("-",D17))) -> C-119 | C17: =IFERROR(MID(A17,FIND("_",A17,FIND("_",A17)+1)+1,LEN(A17)),"") -> JSA | D17: Constituciones-119 | E17: 38608 | F17: 38611 | I17: 8475 | J17: 8
A18: {=IFERROR(_xlfn.XLOOKUP(1,(Hoja1!$B$5:$B$1097=B18)*(Hoja1!$E$5:$E$1097=_xlfn.MAXIFS(Hoja1!$E$5:$E$1097,Hoja1!$B$5:$B$1097,B18,Hoja1!$E$5:$E$1097,"<="&E18)),Hoja1!$C$5:$C$1097,""),"")} -> CONST_205_JSA | B18: =IF(LEFT(D18,1)="T","T-","C-")&TRIM(RIGHT(D18,LEN(D18)-SEARCH("-",D18))) -> C-205 | C18: =IFERROR(MID(A18,FIND("_",A18,FIND("_",A18)+1)+1,LEN(A18)),"") -> JSA | D18: Constituciones-205 | E18: 38608 | F18: 38611 | I18: 7098 | J18: 5
A19: {=IFERROR(_xlfn.XLOOKUP(1,(Hoja1!$B$5:$B$1097=B19)*(Hoja1!$E$5:$E$1097=_xlfn.MAXIFS(Hoja1!$E$5:$E$1097,Hoja1!$B$5:$B$1097,B19,Hoja1!$E$5:$E$1097,"<="&E19)),Hoja1!$C$5:$C$1097,""),"")} -> CONST_206_JSA | B19: =IF(LEFT(D19,1)="T","T-","C-")&TRIM(RIGHT(D19,LEN(D19)-SEARCH("-",D19))) -> C-206 | C19: =IFERROR(MID(A19,FIND("_",A19,FIND("_",A19)+1)+1,LEN(A19)),"") -> JSA | D19: Constituciones-206 | E19: 38608 | F19: 38611 | I19: 9887 | J19: 7
A20: {=IFERROR(_xlfn.XLOOKUP(1,(Hoja1!$B$5:$B$1097=B20)*(Hoja1!$E$5:$E$1097=_xlfn.MAXIFS(Hoja1!$E$5:$E$1097,Hoja1!$B$5:$B$1097,B20,Hoja1!$E$5:$E$1097,"<="&E20)),Hoja1!$C$5:$C$1097,""),"")} -> CONST_211_JSA | B20: =IF(LEFT(D20,1)="T","T-","C-")&TRIM(RIGHT(D20,LEN(D20)-SEARCH("-",D20))) -> C-211 | C20: =IFERROR(MID(A20,FIND("_",A20,FIND("_",A20)+1)+1,LEN(A20)),"") -> JSA | D20: Constituciones-211 | E20: 38608 | F20: 38611 | I20: 10170 | J20: 6.5
A21: {=IFERROR(_xlfn.XLOOKUP(1,(Hoja1!$B$5:$B$1097=B21)*(Hoja1!$E$5:$E$1097=_xlfn.MAXIFS(Hoja1!$E$5:$E$1097,Hoja1!$B$5:$B$1097,B21,Hoja1!$E$5:$E$1097,"<="&E21)),Hoja1!$C$5:$C$1097,""),"")} -> CONST_223_JSA | B21: =IF(LEFT(D21,1)="T","T-","C-")&TRIM(RIGHT(D21,LEN(D21)-SEARCH("-",D21))) -> C-223 | C21: =IFERROR(MID(A21,FIND("_",A21,FIND("_",A21)+1)+1,LEN(A21)),"") -> JSA | D21: Constituciones-223 | E21: 38609 | F21: 38613 | I21: 34515 | J21: 7.5
A22: {=IFERROR(_xlfn.XLOOKUP(1,(Hoja1!$B$5:$B$1097=B22)*(Hoja1!$E$5:$E$1097=_xlfn.MAXIFS(Hoja1!$E$5:$E$1097,Hoja1!$B$5:$B$1097,B22,Hoja1!$E$5:$E$1097,"<="&E22)),Hoja1!$C$5:$C$1097,""),"")} -> CONST_512_JSA | B22: =IF(LEFT(D22,1)="T","T-","C-")&TRIM(RIGHT(D22,LEN(D22)-SEARCH("-",D22))) -> C-512 | C22: =IFERROR(MID(A22,FIND("_",A22,FIND("_",A22)+1)+1,LEN(A22)),"") -> JSA | D22: Constituciones-512 | E22: 38609 | F22: 38613 | I22: 24615 | J22: 8
A23: {=IFERROR(_xlfn.XLOOKUP(1,(Hoja1!$B$5:$B$1097=B23)*(Hoja1!$E$5:$E$1097=_xlfn.MAXIFS(Hoja1!$E$5:$E$1097,Hoja1!$B$5:$B$1097,B23,Hoja1!$E$5:$E$1097,"<="&E23)),Hoja1!$C$5:$C$1097,""),"")} -> CONST_527_JSA | B23: =IF(LEFT(D23,1)="T","T-","C-")&TRIM(RIGHT(D23,LEN(D23)-SEARCH("-",D23))) -> C-527 | C23: =IFERROR(MID(A23,FIND("_",A23,FIND("_",A23)+1)+1,LEN(A23)),"") -> JSA | D23: Constituciones-527 | E23: 38609 | F23: 38613 | I23: 58704 | J23: 8
A24: {=IFERROR(_xlfn.XLOOKUP(1,(Hoja1!$B$5:$B$1097=B24)*(Hoja1!$E$5:$E$1097=_xlfn.MAXIFS(Hoja1!$E$5:$E$1097,Hoja1!$B$5:$B$1097,B24,Hoja1!$E$5:$E$1097,"<="&E24)),Hoja1!$C$5:$C$1097,""),"")} -> CONST_557_JSA | B24: =IF(LEFT(D24,1)="T","T-","C-")&TRIM(RIGHT(D24,LEN(D24)-SEARCH("-",D24))) -> C-557 | C24: =IFERROR(MID(A24,FIND("_",A24,FIND("_",A24)+1)+1,LEN(A24)),"") -> JSA | D24: Constituciones-557 | E24: 38617 | F24: 38620 | I24: 13713 | J24: 8
A25: {=IFERROR(_xlfn.XLOOKUP(1,(Hoja1!$B$5:$B$1097=B25)*(Hoja1!$E$5:$E$1097=_xlfn.MAXIFS(Hoja1!$E$5:$E$1097,Hoja1!$B$5:$B$1097,B25,Hoja1!$E$5:$E$1097,"<="&E25)),Hoja1!$C$5:$C$1097,""),"")} -> CONST_209D_KTIA | B25: =IF(LEFT(D25,1)="T","T-","C-")&TRIM(RIGHT(D25,LEN(D25)-SEARCH("-",D25))) -> C-209D | C25: =IFERROR(MID(A25,FIND("_",A25,FIND("_",A25)+1)+1,LEN(A25)),"") -> KTIA | D25: Constituciones-209D | E25: 38617 | F25: 38620 | I25: 36218 | J25: 9
A26: {=IFERROR(_xlfn.XLOOKUP(1,(Hoja1!$B$5:$B$1097=B26)*(Hoja1!$E$5:$E$1097=_xlfn.MAXIFS(Hoja1!$E$5:$E$1097,Hoja1!$B$5:$B$1097,B26,Hoja1!$E$5:$E$1097,"<="&E26)),Hoja1!$C$5:$C$1097,""),"")} | B26: =IF(LEFT(D26,1)="T","T-","C-")&TRIM(RIGHT(D26,LEN(D26)-SEARCH("-",D26))) -> C-195T | C26: =IFERROR(MID(A26,FIND("_",A26,FIND("_",A26)+1)+1,LEN(A26)),"") | D26: Constituciones-195T | E26: 38621 | F26: 38623 | I26: 9127 | J26: 6
A27: {=IFERROR(_xlfn.XLOOKUP(1,(Hoja1!$B$5:$B$1097=B27)*(Hoja1!$E$5:$E$1097=_xlfn.MAXIFS(Hoja1!$E$5:$E$1097,Hoja1!$B$5:$B$1097,B27,Hoja1!$E$5:$E$1097,"<="&E27)),Hoja1!$C$5:$C$1097,""),"")} | B27: =IF(LEFT(D27,1)="T","T-","C-")&TRIM(RIGHT(D27,LEN(D27)-SEARCH("-",D27))) -> C-195T | C27: =IFERROR(MID(A27,FIND("_",A27,FIND("_",A27)+1)+1,LEN(A27)),"") | D27: Constituciones-195T | E27: 38621 | F27: 38623 | I27: 15861 | J27: 6
A28: {=IFERROR(_xlfn.XLOOKUP(1,(Hoja1!$B$5:$B$1097=B28)*(Hoja1!$E$5:$E$1097=_xlfn.MAXIFS(Hoja1!$E$5:$E$1097,Hoja1!$B$5:$B$1097,B28,Hoja1!$E$5:$E$1097,"<="&E28)),Hoja1!$C$5:$C$1097,""),"")} -> CONST_199_JSA | B28: =IF(LEFT(D28,1)="T","T-","C-")&TRIM(RIGHT(D28,LEN(D28)-SEARCH("-",D28))) -> C-199 | C28: =IFERROR(MID(A28,FIND("_",A28,FIND("_",A28)+1)+1,LEN(A28)),"") -> JSA | D28: Constituciones-199 | E28: 38621 | F28: 38623 | I28: 40786 | J28: 6
... A34: {=IFERROR(_xlfn.XLOOKUP(1,(Hoja1!$B$5:$B$1097=B34)*(Hoja1!$E$5:$E$1097=_xlfn.MAXIFS(Hoja1!$E$5:$E$1097,Hoja1!$B$5:$B$1097,B34,Hoja1!$E$5:$E$1097,"<="&E34)),Hoja1!$C$5:$C$1097,""),"")} -> CONST_202_JSA | B34: =IF(LEFT(D34,1)="T","T-","C-")&TRIM(RIGHT(D34,LEN(D34)-SEARCH("-",D34))) -> C-202 | C34: =IFERROR(MID(A34,FIND("_",A34,FIND("_",A34)+1)+1,LEN(A34)),"") -> JSA | D34: Constituciones-202 | E34: 38630 | F34: 38635 | I34: 24242 | J34: 9
A35: {=IFERROR(_xlfn.XLOOKUP(1,(Hoja1!$B$5:$B$1097=B35)*(Hoja1!$E$5:$E$1097=_xlfn.MAXIFS(Hoja1!$E$5:$E$1097,Hoja1!$B$5:$B$1097,B35,Hoja1!$E$5:$E$1097,"<="&E35)),Hoja1!$C$5:$C$1097,""),"")} -> CONST_175D_KTIA | B35: =IF(LEFT(D35,1)="T","T-","C-")&TRIM(RIGHT(D35,LEN(D35)-SEARCH("-",D35))) -> C-175D | C35: =IFERROR(MID(A35,FIND("_",A35,FIND("_",A35)+1)+1,LEN(A35)),"") -> KTIA | D35: Constituciones-175D | E35: 38736 | F35: 38740 | G35: 0.9597 | H35: 15.96 | I35: 19858 | J35: 9
A36: {=IFERROR(_xlfn.XLOOKUP(1,(Hoja1!$B$5:$B$1097=B36)*(Hoja1!$E$5:$E$1097=_xlfn.MAXIFS(Hoja1!$E$5:$E$1097,Hoja1!$B$5:$B$1097,B36,Hoja1!$E$5:$E$1097,"<="&E36)),Hoja1!$C$5:$C$1097,""),"")} -> TMLP_27_JSA | B36: =IF(LEFT(D36,1)="T","T-","C-")&TRIM(RIGHT(D36,LEN(D36)-SEARCH("-",D36))) -> T-27 | C36: =IFERROR(MID(A36,FIND("_",A36,FIND("_",A36)+1)+1,LEN(A36)),"") -> JSA | D36: Tamaulipas -27 | E36: 38735 | F36: 38740 | G36: 0.9497 | H36: 17.49
A37: {=IFERROR(_xlfn.XLOOKUP(1,(Hoja1!$B$5:$B$1097=B37)*(Hoja1!$E$5:$E$1097=_xlfn.MAXIFS(Hoja1!$E$5:$E$1097,Hoja1!$B$5:$B$1097,B37,Hoja1!$E$5:$E$1097,"<="&E37)),Hoja1!$C$5:$C$1097,""),"")} -> TMLP_27_JSA | B37: =IF(LEFT(D37,1)="T","T-","C-")&TRIM(RIGHT(D37,LEN(D37)-SEARCH("-",D37))) -> T-27 | C37: =IFERROR(MID(A37,FIND("_",A37,FIND("_",A37)+1)+1,LEN(A37)),"") -> JSA | D37: Tamaulipas -27 | E37: 38761 | F37: 38783 | G37: 0.9648 | H37: 15.16
A38: {=IFERROR(_xlfn.XLOOKUP(1,(Hoja1!$B$5:$B$1097=B38)*(Hoja1!$E$5:$E$1097=_xlfn.MAXIFS(Hoja1!$E$5:$E$1097,Hoja1!$B$5:$B$1097,B38,Hoja1!$E$5:$E$1097,"<="&E38)),Hoja1!$C$5:$C$1097,""),"")} -> CONST_134D_KTIA | B38: =IF(LEFT(D38,1)="T","T-","C-")&TRIM(RIGHT(D38,LEN(D38)-SEARCH("-",D38))) -> C-134D | C38: =IFERROR(MID(A38,FIND("_",A38,FIND("_",A38)+1)+1,LEN(A38)),"") -> KTIA | D38: Constituciones-134D | E38: 38893 | F38: 38896 | G38: 0.9909 | H38: 11.31 | J38: 6.5
A39: {=IFERROR(_xlfn.XLOOKUP(1,(Hoja1!$B$5:$B$1097=B39)*(Hoja1!$E$5:$E$1097=_xlfn.MAXIFS(Hoja1!$E$5:$E$1097,Hoja1!$B$5:$B$1097,B39,Hoja1!$E$5:$E$1097,"<="&E39)),Hoja1!$C$5:$C$1097,""),"")} -> CONST_134D_KTIA | B39: =IF(LEFT(D39,1)="T","T-","C-")&TRIM(RIGHT(D39,LEN(D39)-SEARCH("-",D39))) -> C-134D | C39: =IFERROR(MID(A39,FIND("_",A39,FIND("_",A39)+1)+1,LEN(A39)),"") -> KTIA | D39: Constituciones-134D | E39: 38896 | F39: 38897 | I39: 134662 | J39: 6.5
A40: {=IFERROR(_xlfn.XLOOKUP(1,(Hoja1!$B$5:$B$1097=B40)*(Hoja1!$E$5:$E$1097=_xlfn.MAXIFS(Hoja1!$E$5:$E$1097,Hoja1!$B$5:$B$1097,B40,Hoja1!$E$5:$E$1097,"<="&E40)),Hoja1!$C$5:$C$1097,""),"")} | B40: =IF(LEFT(D40,1)="T","T-","C-")&TRIM(RIGHT(D40,LEN(D40)-SEARCH("-",D40))) -> C-138 | C40: =IFERROR(MID(A40,FIND("_",A40,FIND("_",A40)+1)+1,LEN(A40)),"") | D40: Constituciones-138 | F40: 38929 | G40: 0.9111 | H40: 23.81 | I40: 25863.196 | J40: 9
A41: {=IFERROR(_xlfn.XLOOKUP(1,(Hoja1!$B$5:$B$1097=B41)*(Hoja1!$E$5:$E$1097=_xlfn.MAXIFS(Hoja1!$E$5:$E$1097,Hoja1!$B$5:$B$1097,B41,Hoja1!$E$5:$E$1097,"<="&E41)),Hoja1!$C$5:$C$1097,""),"")} -> CONST_134D_KTIA | B41: =IF(LEFT(D41,1)="T","T-","C-")&TRIM(RIGHT(D41,LEN(D41)-SEARCH("-",D41))) -> C-134D | C41: =IFERROR(MID(A41,FIND("_",A41,FIND("_",A41)+1)+1,LEN(A41)),"") -> KTIA | D41: Constituciones-134D | E41: 39147 | F41: 39151 | G41: 0.9659 | H41: 15
A42: {=IFERROR(_xlfn.XLOOKUP(1,(Hoja1!$B$5:$B$1097=B42)*(Hoja1!$E$5:$E$1097=_xlfn.MAXIFS(Hoja1!$E$5:$E$1097,Hoja1!$B$5:$B$1097,B42,Hoja1!$E$5:$E$1097,"<="&E42)),Hoja1!$C$5:$C$1097,""),"")} -> CONST_138_JSA | B42: =IF(LEFT(D42,1)="T","T-","C-")&TRIM(RIGHT(D42,LEN(D42)-SEARCH("-",D42))) -> C-138 | C42: =IFERROR(MID(A42,FIND("_",A42,FIND("_",A42)+1)+1,LEN(A42)),"") -> JSA | D42: Constituciones-138 | E42: 39147 | F42: 39151 | G42: 0.9793 | H42: 12.99 | I42: 30210.661 | J42: 9
A43: {=IFERROR(_xlfn.XLOOKUP(1,(Hoja1!$B$5:$B$1097=B43)*(Hoja1!$E$5:$E$1097=_xlfn.MAXIFS(Hoja1!$E$5:$E$1097,Hoja1!$B$5:$B$1097,B43,Hoja1!$E$5:$E$1097,"<="&E43)),Hoja1!$C$5:$C$1097,""),"")} -> CONST_134D_KTIA | B43: =IF(LEFT(D43,1)="T","T-","C-")&TRIM(RIGHT(D43,LEN(D43)-SEARCH("-",D43))) -> C-134D | C43: =IFERROR(MID(A43,FIND("_",A43,FIND("_",A43)+1)+1,LEN(A43)),"") -> KTIA | D43: Constituciones-134D | E43: 39147 | F43: 39156 | G43: 0.9697 | H43: 14.42
A44: {=IFERROR(_xlfn.XLOOKUP(1,(Hoja1!$B$5:$B$1097=B44)*(Hoja1!$E$5:$E$1097=_xlfn.MAXIFS(Hoja1!$E$5:$E$1097,Hoja1!$B$5:$B$1097,B44,Hoja1!$E$5:$E$1097,"<="&E44)),Hoja1!$C$5:$C$1097,""),"")} -> CONST_135_JSA | B44: =IF(LEFT(D44,1)="T","T-","C-")&TRIM(RIGHT(D44,LEN(D44)-SEARCH("-",D44))) -> C-135 | C44: =IFERROR(MID(A44,FIND("_",A44,FIND("_",A44)+1)+1,LEN(A44)),"") -> JSA | D44: Constituciones-135 | E44: 39147 | F44: 39156 | G44: 0.9813 | H44: 12.7
A45: {=IFERROR(_xlfn.XLOOKUP(1,(Hoja1!$B$5:$B$1097=B45)*(Hoja1!$E$5:$E$1097=_xlfn.MAXIFS(Hoja1!$E$5:$E$1097,Hoja1!$B$5:$B$1097,B45,Hoja1!$E$5:$E$1097,"<="&E45)),Hoja1!$C$5:$C$1097,""),"")} -> CONST_589_JSA | B45: =IF(LEFT(D45,1)="T","T-","C-")&TRIM(RIGHT(D45,LEN(D45)-SEARCH("-",D45))) -> C-589 | C45: =IFERROR(MID(A45,FIND("_",A45,FIND("_",A45)+1)+1,LEN(A45)),"") -> JSA | D45: Constituciones-589 | E45: 39147 | F45: 39156 | G45: 0.9903 | H45: 11.4
...

Sheet Stiff
A1: Terminacion | B1: Pozo | C1: ID | D1: No. | E1: Formación | F1: Intervalo | G1: Profundidad | H1: Fecha de Muestreo | I1: Hora | J1: Fecha análisis | K1: PH | L1: Olor | M1: Color | N1: Aspecto | O1: Densidad gr/cm3 | P1: Temperatura °C | Q1: Oxígeno Disuelto mg/L | R1: Acido Suflhídrico mg/L | S1: Bióxido de Carbono mg/L | T1: Sodio mg/L | U1: Calcio mg/L | V1: Magnesio mg/L | W1: Fierro mg/L | X1: Cloruros mg/L | Y1: Bicarbonatos mg/L | Z1: Sulfatos mg/L | AA1: Carbonatos mg/L | AB1: Salinidad "NaCl" ppm | AC1: Salinidad Equivalente ppm | AD1: Acidez mg/L | AE1: Solidos Disueltos mg/l | AF1: Oxido Ferrico mg/l | AG1: Dureza Total mg/l | AH1: Indice de Estabilidad SD | AI1: Alcalinidad "F" mg/L | AJ1: Alcalinidad "M" mg/L | AK1: Sodio meq/L | AL1: Calcio meq/L | AM1: Magnesio meq/L | AN1: Fierro meq/L | AO1: Cloruros meqL | AP1: Bicarbonatos meq/L | AQ1: Sulfatos meq/L | AR1: Carbonatos meq/L | AS1: Observaciones
A2: {=IFERROR(_xlfn.XLOOKUP(1,(Hoja1!$B$5:$B$1097=B2)*(Hoja1!$E$5:$E$1097=_xlfn.MAXIFS(Hoja1!$E$5:$E$1097,Hoja1!$B$5:$B$1097,B2,Hoja1!$E$5:$E$1097,"<="&H2)),Hoja1!$C$5:$C$1097,""),"")} -> CONST_119_JSA | B2: =IF(LEFT(C2,1)="T","T-","C-")&TRIM(RIGHT(C2,LEN(C2)-SEARCH("-",C2))) -> C-119 | C2: Constituciones-119 | D2: 119 | E2: Sin Dato | F2: S/D | G2: S/D | H2: 38588 | I2: S/D | J2: 38593 | K2: 7 | L2: fétido | M2: incoloro | N2: transparen | O2: 1.0003 | P2: 23 | Q2: 0 | R2: 0.34 | S2: 139.63 | T2: 2993.2 | U2: 240.5 | V2: 680.9 | W2: 0 | X2: 6166 | Y2: 686.39 | Z2: 625 | AA2: 0 | AB2: 10162.062 | AD2: 5.275 | AE2: 11391.99 | AF2: 0 | AG2: 3403 | AH2: 531.96 | AK2: 130.14547 | AL2: 12.00095 | AM2: 55.997216 | AN2: 0 | AO2: 173.8812 | AP2: 11.249932 | AQ2: 13.0125 | AR2: 0
A3: {=IFERROR(_xlfn.XLOOKUP(1,(Hoja1!$B$5:$B$1097=B3)*(Hoja1!$E$5:$E$1097=_xlfn.MAXIFS(Hoja1!$E$5:$E$1097,Hoja1!$B$5:$B$1097,B3,Hoja1!$E$5:$E$1097,"<="&H3)),Hoja1!$C$5:$C$1097,""),"")} -> CONST_134_JSA | B3: =IF(LEFT(C3,1)="T","T-","C-")&TRIM(RIGHT(C3,LEN(C3)-SEARCH("-",C3))) -> C-134 | C3: Constituciones-134 | D3: 134 | E3: Sin Dato | F3: S/D | G3: S/D | H3: 38588 | I3: S/D | J3: 38593 | K3: 6 | L3: inodoro | M3: café claro | N3: lig. Turbio | O3: 0.9983 | P3: 23 | Q3: 0 | R3: 206.88 | S3: 69.81 | T3: 3684.7 | U3: 541.1 | V3: 547.2 | W3: 14.5 | X3: 7238 | Y3: 411.84 | Z3: 1050 | AA3: 0 | AB3: 11952.702 | AD3: 5.275 | AE3: 13487.34 | AF3: 20.73065 | AG3: 3603 | AH3: 319.17 | AK3: 160.20094 | AL3: 27.00089 | AM3: 45.001728 | AN3: 0.5191 | AO3: 204.1116 | AP3: 6.7500576 | AQ3: 21.861 | AR3: 0
A4: {=IFERROR(_xlfn.XLOOKUP(1,(Hoja1!$B$5:$B$1097=B4)*(Hoja1!$E$5:$E$1097=_xlfn.MAXIFS(Hoja1!$E$5:$E$1097,Hoja1!$B$5:$B$1097,B4,Hoja1!$E$5:$E$1097,"<="&H4)),Hoja1!$C$5:$C$1097,""),"")} -> CONST_169D_JSA | B4: =IF(LEFT(C4,1)="T","T-","C-")&TRIM(RIGHT(C4,LEN(C4)-SEARCH("-",C4))) -> C-169D | C4: Constituciones-169D | D4: 169D | E4: Sin Dato | F4: S/D | G4: S/D | H4: 38588 | I4: S/D | J4: 38593 | K4: 6 | L4: Aceitoso | M4: café claro | N4: lig. Turbio | O4: 0.9987 | P4: 22 | Q4: 0 | R4: 69.19 | S4: 59.84 | T4: 3353.2 | U4: 420.8 | V4: 620.1 | W4: 11.5 | X4: 6434 | Y4: 274.56 | Z4: 1550 | AA4: 0 | AB4: 10620.735 | AD4: 5.275 | AE4: 12664.16 | AF4: 16.44155 | AG4: 3603 | AH4: 212.78 | AK4: 145.80319 | AL4: 20.99792 | AM4: 50.997024 | AN4: 0.4117 | AO4: 181.4388 | AP4: 4.5000384 | AQ4: 32.271 | AR4: 0
A5: {=IFERROR(_xlfn.XLOOKUP(1,(Hoja1!$B$5:$B$1097=B5)*(Hoja1!$E$5:$E$1097=_xlfn.MAXIFS(Hoja1!$E$5:$E$1097,Hoja1!$B$5:$B$1097,B5,Hoja1!$E$5:$E$1097,"<="&H5)),Hoja1!$C$5:$C$1097,""),"")} | B5: =IF(LEFT(C5,1)="T","T-","C-")&TRIM(RIGHT(C5,LEN(C5)-SEARCH("-",C5))) -> C-195T | C5: Constituciones-195T | D5: 195T | E5: Sin Dato | F5: S/D | G5: S/D | H5: 38588 | I5: S/D | J5: 38593 | K5: 6 | L5: inoloro | M5: café claro | N5: lig. Turbio | O5: 0.9987 | P5: 22 | Q5: 0 | R5: 4.09 | S5: 39.89 | T5: 1885.8 | U5: 280.6 | V5: 559.3 | W5: 15 | X5: 4021 | Y5: 411.84 | Z5: 1075 | AA5: 0 | AB5: 6637.5468 | AD5: 5.275 | AE5: 8248.54 | AF5: 21.4455 | AG5: 3002 | AH5: 319.17 | AK5: 81.987986 | AL5: 14.00194 | AM5: 45.996832 | AN5: 0.537 | AO5: 113.3922 | AP5: 6.7500576 | AQ5: 22.3815 | AR5: 0
A6: {=IFERROR(_xlfn.XLOOKUP(1,(Hoja1!$B$5:$B$1097=B6)*(Hoja1!$E$5:$E$1097=_xlfn.MAXIFS(Hoja1!$E$5:$E$1097,Hoja1!$B$5:$B$1097,B6,Hoja1!$E$5:$E$1097,"<="&H6)),Hoja1!$C$5:$C$1097,""),"")} -> CONST_196D_KTIA | B6: =IF(LEFT(C6,1)="T","T-","C-")&TRIM(RIGHT(C6,LEN(C6)-SEARCH("-",C6))) -> C-196D | C6: Constituciones-196D | D6: 196D | E6: Sin Dato | F6: S/D | G6: S/D | H6: 38588 | I6: S/D | J6: 38593 | K6: 7 | L6: aceite | M6: obscuro transparente c/sólidos suspendidos | N6: Turbio | O6: 0.9997 | P6: 22 | Q6: 0 | R6: 38.51 | S6: 69.81 | T6: 3160 | U6: 601.2 | V6: 632.3 | W6: 5.5 | X6: 6702 | Y6: 755.03 | Z6: 875 | AA6: 0 | AB6: 11052.062 | AD6: 5.275 | AE6: 12731.03 | AF6: 7.86335 | AG6: 4103 | AH6: 585.15 | AK6: 137.39171 | AL6: 29.99988 | AM6: 52.000352 | AN6: 0.1969 | AO6: 188.9964 | AP6: 12.374942 | AQ6: 18.2175 | AR6: 0
A7: {=IFERROR(_xlfn.XLOOKUP(1,(Hoja1!$B$5:$B$1097=B7)*(Hoja1!$E$5:$E$1097=_xlfn.MAXIFS(Hoja1!$E$5:$E$1097,Hoja1!$B$5:$B$1097,B7,Hoja1!$E$5:$E$1097,"<="&H7)),Hoja1!$C$5:$C$1097,""),"")} -> CONST_199_JSA | B7: =IF(LEFT(C7,1)="T","T-","C-")&TRIM(RIGHT(C7,LEN(C7)-SEARCH("-",C7))) -> C-199 | C7: Constituciones-199 | D7: 199 | E7: Sin Dato | F7: S/D | G7: S/D | H7: 38588 | I7: S/D | J7: 38593 | K7: 6 | L7: aceite | M7: café muy claro | N7: transparen | O7: 0.9963 | P7: 23 | Q7: 0 | R7: 107.36 | S7: 29.92 | T7: 3276 | U7: 481 | V7: 158.1 | W7: 1.75 | X7: 6166 | Y7: 343.2 | Z7: 0 | AA7: 0 | AB7: 10202.861 | AD7: 5.275 | AE7: 10426.05 | AF7: 2.501975 | AG7: 1851 | AH7: 265.98 | AK7: 142.43955 | AL7: 24.0019 | AM7: 13.002144 | AN7: 0.06265 | AO7: 173.8812 | AP7: 5.625048 | AQ7: 0 | AR7: 0
A8: {=IFERROR(_xlfn.XLOOKUP(1,(Hoja1!$B$5:$B$1097=B8)*(Hoja1!$E$5:$E$1097=_xlfn.MAXIFS(Hoja1!$E$5:$E$1097,Hoja1!$B$5:$B$1097,B8,Hoja1!$E$5:$E$1097,"<="&H8)),Hoja1!$C$5:$C$1097,""),"")} -> CONST_201_JSA | B8: =IF(LEFT(C8,1)="T","T-","C-")&TRIM(RIGHT(C8,LEN(C8)-SEARCH("-",C8))) -> C-201 | C8: Constituciones-201 | D8: 201 | E8: Sin Dato | F8: S/D | G8: S/D | H8: 38588 | I8: S/D | J8: 38593 | K8: 5 | L8: aceite | M8: incoloro | N8: transparen | O8: 0.9987 | P8: 22 | Q8: 0 | R8: 4.09 | S8: 29.92 | T8: 3080.9 | U8: 440.9 | V8: 462.1 | W8: 1.75 | X8: 6702 | Y8: 274.56 | Z8: 25 | AA8: 0 | AB8: 11063.128 | AD8: 5.275 | AE8: 10987.21 | AF8: 2.501975 | AG8: 3002 | AH8: 212.78 | AK8: 133.95027 | AL8: 22.00091 | AM8: 38.003104 | AN8: 0.06265 | AO8: 188.9964 | AP8: 4.5000384 | AQ8: 0.5205 | AR8: 0
A9: {=IFERROR(_xlfn.XLOOKUP(1,(Hoja1!$B$5:$B$1097=B9)*(Hoja1!$E$5:$E$1097=_xlfn.MAXIFS(Hoja1!$E$5:$E$1097,Hoja1!$B$5:$B$1097,B9,Hoja1!$E$5:$E$1097,"<="&H9)),Hoja1!$C$5:$C$1097,""),"")} -> CONST_211_JSA | B9: =IF(LEFT(C9,1)="T","T-","C-")&TRIM(RIGHT(C9,LEN(C9)-SEARCH("-",C9))) -> C-211 | C9: Constituciones-211 | D9: 211 | E9: Sin Dato | F9: S/D | G9: S/D | H9: 38588 | I9: S/D | J9: 38593 | K9: 6 | L9: aceite | M9: café muy claro | N9: transparen | O9: 0.9987 | P9: 22 | Q9: 0 | R9: 103.61 | S9: 39.89 | T9: 2635.8 | U9: 400.8 | V9: 620.1 | W9: 1.75 | X9: 6166 | Y9: 274.56 | Z9: 350 | AA9: 0 | AB9: 10178.342 | AD9: 5275 | AE9: 10449.01 | AF9: 2.501975 | AG9: 3553 | AH9: 212.78 | AK9: 114.60864 | AL9: 19.99992 | AM9: 50.997024 | AN9: 0.06265 | AO9: 173.8812 | AP9: 4.5000384 | AQ9: 7.287 | AR9: 0
A10: {=IFERROR(_xlfn.XLOOKUP(1,(Hoja1!$B$5:$B$1097=B10)*(Hoja1!$E$5:$E$1097=_xlfn.MAXIFS(Hoja1!$E$5:$E$1097,Hoja1!$B$5:$B$1097,B10,Hoja1!$E$5:$E$1097,"<="&H10)),Hoja1!$C$5:$C$1097,""),"")} -> CONST_221_JSA | B10: =IF(LEFT(C10,1)="T","T-","C-")&TRIM(RIGHT(C10,LEN(C10)-SEARCH("-",C10))) -> C-221 | C10: Constituciones-221 | D10: 221 | E10: Sin Dato | F10: S/D | G10: S/D | H10: 38588 | I10: S/D | J10: 38593 | K10: 7 | L10: Aceitoso | M10: café | N10: Turbio | O10: 0.9987 | P10: 22 | Q10: 0 | R10: 103.61 | S10: 49.87 | T10: 3146.4 | U10: 400.8 | V10: 705.3 | W10: 1 | X10: 6702 | Y10: 274.56 | Z10: 1025 | AA10: 0 | AB10: 11063.128 | AD10: 5.275 | AE10: 12255.06 | AF10: 1.4297 | AG10: 3903 | AH10: 212.78 | AK10: 136.79735 | AL10: 19.99992 | AM10: 58.003872 | AN10: 0.0358 | AO10: 188.9964 | AP10: 4.5000384 | AQ10: 21.3405 | AR10: 0
A11: {=IFERROR(_xlfn.XLOOKUP(1,(Hoja1!$B$5:$B$1097=B11)*(Hoja1!$E$5:$E$1097=_xlfn.MAXIFS(Hoja1!$E$5:$E$1097,Hoja1!$B$5:$B$1097,B11,Hoja1!$E$5:$E$1097,"<="&H11)),Hoja1!$C$5:$C$1097,""),"")} -> CONST_557_JSA | B11: =IF(LEFT(C11,1)="T","T-","C-")&TRIM(RIGHT(C11,LEN(C11)-SEARCH("-",C11))) -> C-557 | C11: Constituciones-557 | D11: 557 | E11: Sin Dato | F11: S/D | G11: S/D | H11: 38588 | I11: S/D | J11: 38593 | K11: 8 | L11: aceite | M11: verde claro | N11: lig. Turbio | O11: 0.9987 | P11: 22 | Q11: 0 | R11: 4.09 | S11: 29.92 | T11: 3805 | U11: 320.6 | V11: 656.6 | W11: 1 | X11: 6702 | Y11: 549.12 | Z11: 1800 | AA11: 0 | AB11: 11063.128 | AD11: 5.275 | AE11: 13834.32 | AF11: 1.4297 | AG11: 3503 | AH11: 425.57 | AK11: 165.43995 | AL11: 15.99794 | AM11: 53.998784 | AN11: 0.0358 | AO11: 188.9964 | AP11: 9.0000768 | AQ11: 37.476 | AR11: 0
A12: {=IFERROR(_xlfn.XLOOKUP(1,(Hoja1!$B$5:$B$1097=B12)*(Hoja1!$E$5:$E$1097=_xlfn.MAXIFS(Hoja1!$E$5:$E$1097,Hoja1!$B$5:$B$1097,B12,Hoja1!$E$5:$E$1097,"<="&H12)),Hoja1!$C$5:$C$1097,""),"")} | B12: =IF(LEFT(C12,1)="T","T-","C-")&TRIM(RIGHT(C12,LEN(C12)-SEARCH("-",C12))) -> C-1001 | C12: Constituciones-1001 | D12: 1001 | E12: Sin Dato | F12: S/D | G12: S/D | H12: 38588 | I12: S/D | J12: 38593 | K12: 7 | L12: fétido | M12: ´blancusco | N12: lig. Turbio | O12: 1.0013 | P12: 23 | Q12: 0 | R12: -30.33 | S12: 49.87 | T12: 6449.5 | U12: 320.6 | V12: 121.6 | W12: 12.75 | X12: 10455 | Y12: 480.48 | Z12: 200 | AA12: 0 | AB12: 17213.469 | AD12: 5.275 | AE12: 18039.93 | AF12: 18.228675 | AG12: 1301 | AH12: 372.37 | AK12: 280.41529 | AL12: 15.99794 | AM12: 10.000384 | AN12: 0.45645 | AO12: 294.831 | AP12: 7.8750672 | AQ12: 4.164 | AR12: 0
A13: {=IFERROR(_xlfn.XLOOKUP(1,(Hoja1!$B$5:$B$1097=B13)*(Hoja1!$E$5:$E$1097=_xlfn.MAXIFS(Hoja1!$E$5:$E$1097,Hoja1!$B$5:$B$1097,B13,Hoja1!$E$5:$E$1097,"<="&H13)),Hoja1!$C$5:$C$1097,""),"")} -> CONST_199_JSA | B13: =IF(LEFT(C13,1)="T","T-","C-")&TRIM(RIGHT(C13,LEN(C13)-SEARCH("-",C13))) -> C-199 | C13: Constituciones-199 | D13: 199 | E13: Sin Dato | F13: S/D | G13: S/D | H13: 38528 | I13: 0.52777778 | J13: 38532 | K13: 7 | L13: - | M13: 0 | N13: 0 | O13: 1.0156 | P13: 25 | Q13: 0 | R13: 69.19 | S13: 0 | T13: 4478.2 | U13: 681.4 | V13: 340.5 | W13: 33 | X13: 8808 | Y13: 549.12 | Z13: 25 | AA13: 0 | AB13: 14297.602 | AD13: 42.196 | AE13: 14915.22 | AF13: 47.1801 | AG13: 3102 | AH13: 425.57 | AK13: 194.7202 | AL13: 34.00186 | AM13: 28.00272 | AN13: 1.1814 | AO13: 248.3856 | AP13: 9.0000768 | AQ13: 0.5205 | AR13: 0
A14: {=IFERROR(_xlfn.XLOOKUP(1,(Hoja1!$B$5:$B$1097=B14)*(Hoja1!$E$5:$E$1097=_xlfn.MAXIFS(Hoja1!$E$5:$E$1097,Hoja1!$B$5:$B$1097,B14,Hoja1!$E$5:$E$1097,"<="&H14)),Hoja1!$C$5:$C$1097,""),"")} -> CONST_199_JSA | B14: =IF(LEFT(C14,1)="T","T-","C-")&TRIM(RIGHT(C14,LEN(C14)-SEARCH("-",C14))) -> C-199 | C14: Constituciones-199 | D14: 199 | E14: Sin Dato | F14: S/D | G14: S/D | H14: 38528 | I14: 0.5625 | J14: 38532 | K14: 7 | L14: - | M14: 0 | N14: 0 | O14: 0.9956 | P14: 25 | Q14: 0 | R14: 69.19 | S14: 89.76 | T14: 1796.1 | U14: 601.2 | V14: 121.6 | W14: 17.5 | X14: 3875 | Y14: 480.48 | Z14: 75 | AA14: 0 | AB14: 6416.4586 | AD14: 15.824 | AE14: 6966.88 | AF14: 25.01975 | AG14: 2002 | AH14: 372.37 | AK14: 78.084803 | AL14: 29.99988 | AM14: 10.000384 | AN14: 0.6265 | AO14: 109.275 | AP14: 7.8750672 | AQ14: 1.5615 | AR14: 0
A15: {=IFERROR(_xlfn.XLOOKUP(1,(Hoja1!$B$5:$B$1097=B15)*(Hoja1!$E$5:$E$1097=_xlfn.MAXIFS(Hoja1!$E$5:$E$1097,Hoja1!$B$5:$B$1097,B15,Hoja1!$E$5:$E$1097,"<="&H15)),Hoja1!$C$5:$C$1097,""),"")} -> CONST_201_JSA | B15: =IF(LEFT(C15,1)="T","T-","C-")&TRIM(RIGHT(C15,LEN(C15)-SEARCH("-",C15))) -> C-201 | C15: Constituciones-201 | D15: 201 | E15: Sin Dato | F15: S/D | G15: S/D | H15: 38529 | I15: S/D | J15: 38532 | K15: 7 | L15: - | M15: 0 | N15: 0 | O15: 1.0156 | P15: 25 | Q15: 0 | R15: 69.19 | S15: 84.77 | T15: 3409.5 | U15: 601.2 | V15: 279.7 | W15: 2.25 | X15: 6694 | Y15: 480.48 | Z15: 225 | AA15: 0 | AB15: 10866.047 | AD15: 15.824 | AE15: 11692.13 | AF15: 3.216825 | AG15: 2652 | AH15: 372.37 | AK15: 148.24741 | AL15: 29.99988 | AM15: 23.002528 | AN15: 0.08055 | AO15: 188.7708 | AP15: 7.8750672 | AQ15: 4.6845 | AR15: 0
A16: {=IFERROR(_xlfn.XLOOKUP(1,(Hoja1!$B$5:$B$1097=B16)*(Hoja1!$E$5:$E$1097=_xlfn.MAXIFS(Hoja1!$E$5:$E$1097,Hoja1!$B$5:$B$1097,B16,Hoja1!$E$5:$E$1097,"<="&H16)),Hoja1!$C$5:$C$1097,""),"")} -> CONST_201_JSA | B16: =IF(LEFT(C16,1)="T","T-","C-")&TRIM(RIGHT(C16,LEN(C16)-SEARCH("-",C16))) -> C-201 | C16: Constituciones-201 | D16: 201 | E16: Sin Dato | F16: S/D | G16: S/D | H16: 38529 | I16: S/D | J16: 38532 | K16: 7 | L16: - | M16: 0 | N16: 0 | O16: 0.9956 | P16: 25 | Q16: 0 | R16: 69.19 | S16: 79.79 | T16: 3055 | U16: 801.6 | V16: 218.9 | W16: 1 | X16: 6341 | Y16: 480.48 | Z16: 200 | AA16: 0 | AB16: 10499.81 | AD16: 10.549 | AE16: 11097.98 | AF16: 1.4297 | AG16: 2902 | AH16: 372.37 | AK16: 132.81729 | AL16: 39.99984 | AM16: 18.002336 | AN16: 0.0358 | AO16: 178.8162 | AP16: 7.8750672 | AQ16: 4.164 | AR16: 0
A17: {=IFERROR(_xlfn.XLOOKUP(1,(Hoja1!$B$5:$B$1097=B17)*(Hoja1!$E$5:$E$1097=_xlfn.MAXIFS(Hoja1!$E$5:$E$1097,Hoja1!$B$5:$B$1097,B17,Hoja1!$E$5:$E$1097,"<="&H17)),Hoja1!$C$5:$C$1097,""),"")} -> CONST_211_JSA | B17: =IF(LEFT(C17,1)="T","T-","C-")&TRIM(RIGHT(C17,LEN(C17)-SEARCH("-",C17))) -> C-211 | C17: Constituciones-211 | D17: 211 | E17: Sin Dato | F17: S/D | G17: S/D | H17: 38529 | I17: S/D | J17: 38532 | K17: 6 | L17: - | M17: 0 | N17: 0 | O17: 0.9956 | P17: 25 | Q17: 0 | R17: 34.76 | S17: 69.81 | T17: 3195.4 | U17: 641.3 | V17: 316.1 | W17: 20.75 | X17: 6694 | Y17: 480.48 | Z17: 50 | AA17: 0 | AB17: 11084.329 | AD17: 15.824 | AE17: 11398.03 | AF17: 29.666275 | AG17: 2902 | AH17: 372.37 | AK17: 138.94708 | AL17: 32.00087 | AM17: 25.996064 | AN17: 0.74285 | AO17: 188.7708 | AP17: 7.8750672 | AQ17: 1.041 | AR17: 0
A18: {=IFERROR(_xlfn.XLOOKUP(1,(Hoja1!$B$5:$B$1097=B18)*(Hoja1!$E$5:$E$1097=_xlfn.MAXIFS(Hoja1!$E$5:$E$1097,Hoja1!$B$5:$B$1097,B18,Hoja1!$E$5:$E$1097,"<="&H18)),Hoja1!$C$5:$C$1097,""),"")} -> CONST_211_JSA | B18: =IF(LEFT(C18,1)="T","T-","C-")&TRIM(RIGHT(C18,LEN(C18)-SEARCH("-",C18))) -> C-211 | C18: Constituciones-211 | D18: 211 | E18: Sin Dato | F18: S/D | G18: S/D | H18: 38529 | I18: S/D | J18: 38532 | K18: 7 | L18: - | M18: 0 | N18: 0 | O18: 1.0156 | P18: 25 | Q18: 0 | R18: 0.34 | S18: 84.77 | T18: 3786.2 | U18: 1002 | V18: 389.1 | W18: 38.75 | X18: 8455 | Y18: 549.12 | Z18: 27.5 | AA18: 0 | AB18: 13724.594 | AD18: 15.824 | AE18: 14247.67 | AF18: 55.400875 | AG18: 4103 | AH18: 425.57 | AK18: 164.61699 | AL18: 49.9998 | AM18: 31.999584 | AN18: 1.38725 | AO18: 238.431 | AP18: 9.0000768 | AQ18: 0.57255 | AR18: 0
A19: {=IFERROR(_xlfn.XLOOKUP(1,(Hoja1!$B$5:$B$1097=B19)*(Hoja1!$E$5:$E$1097=_xlfn.MAXIFS(Hoja1!$E$5:$E$1097,Hoja1!$B$5:$B$1097,B19,Hoja1!$E$5:$E$1097,"<="&H19)),Hoja1!$C$5:$C$1097,""),"")} -> CONST_221_JSA | B19: =IF(LEFT(C19,1)="T","T-","C-")&TRIM(RIGHT(C19,LEN(C19)-SEARCH("-",C19))) -> C-221 | C19: Constituciones-221 | D19: 221 | E19: Sin Dato | F19: S/D | G19: S/D | H19: 38528 | I19: 0.4375 | J19: 38532 | K19: 7 | L19: - | M19: 0 | N19: 0 | O19: 0.9956 | P19: 25 | Q19: 0 | R19: 69.19 | S19: 69.81 | T19: 3371.4 | U19: 801.6 | V19: 267.5 | W19: 4.25 | X19: 7046 | Y19: 549.12 | Z19: 50 | AA19: 0 | AB19: 11667.192 | AD19: 10.549 | AE19: 12089.87 | AF19: 6.076225 | AG19: 3102 | AH19: 425.57 | AK19: 146.58709 | AL19: 39.99984 | AM19: 21.9992 | AN19: 0.15215 | AO19: 198.6972 | AP19: 9.0000768 | AQ19: 1.041 | AR19: 0
A20: {=IFERROR(_xlfn.XLOOKUP(1,(Hoja1!$B$5:$B$1097=B20)*(Hoja1!$E$5:$E$1097=_xlfn.MAXIFS(Hoja1!$E$5:$E$1097,Hoja1!$B$5:$B$1097,B20,Hoja1!$E$5:$E$1097,"<="&H20)),Hoja1!$C$5:$C$1097,""),"")} -> CONST_221_JSA | B20: =IF(LEFT(C20,1)="T","T-","C-")&TRIM(RIGHT(C20,LEN(C20)-SEARCH("-",C20))) -> C-221 | C20: Constituciones-221 | D20: 221 | E20: Sin Dato | F20: S/D | G20: S/D | H20: 38528 | I20: 0.45486111 | J20: 38532 | K20: 7 | L20: - | M20: 0 | N20: 0 | O20: 1.0556 | P20: 25 | Q20: 0 | R20: 69.19 | S20: 59.84 | T20: 8638.1 | U20: 1723.5 | V20: 535 | W20: 1 | X20: 17263 | Y20: 480.48 | Z20: 525 | AA20: 0 | AB20: 26960.346 | AD20: 10.549 | AE20: 29166.08 | AF20: 1.4297 | AG20: 6505 | AH20: 372.37 | AK20: 375.58532 | AL20: 86.00265 | AM20: 43.9984 | AN20: 0.0358 | AO20: 486.8166 | AP20: 7.8750672 | AQ20: 10.9305 | AR20: 0
A21: {=IFERROR(_xlfn.XLOOKUP(1,(Hoja1!$B$5:$B$1097=B21)*(Hoja1!$E$5:$E$1097=_xlfn.MAXIFS(Hoja1!$E$5:$E$1097,Hoja1!$B$5:$B$1097,B21,Hoja1!$E$5:$E$1097,"<="&H21)),Hoja1!$C$5:$C$1097,""),"")} -> CONST_203_JSA | B21: =IF(LEFT(C21,1)="T","T-","C-")&TRIM(RIGHT(C21,LEN(C21)-SEARCH("-",C21))) -> C-203 | C21: Constituciones-203 | D21: 203 | E21: Sin Dato | F21: S/D | G21: S/D | H21: 38630 | I21: S/D | J21: 38664 | K21: 9 | L21: Aceitoso | M21: lig. Café | N21: claro | O21: 1.0115 | P21: 22.5 | Q21: 0 | R21: 0 | S21: 19.95 | T21: 4995.4 | U21: 1242.5 | V21: 462.1 | W21: 0.5 | X21: 10541 | Y21: 360.59 | Z21: 675 | AA21: 0 | AB21: 17180.053 | AD21: 5.275 | AE21: 18277.09 | AF21: 0.71485 | AG21: 5004 | AH21: 319.17 | AK21: 217.19802 | AL21: 62.00075 | AM21: 38.003104 | AN21: 0.0179 | AO21: 297.2562 | AP21: 5.9100701 | AQ21: 14.0535 | AR21: 0
A22: {=IFERROR(_xlfn.XLOOKUP(1,(Hoja1!$B$5:$B$1097=B22)*(Hoja1!$E$5:$E$1097=_xlfn.MAXIFS(Hoja1!$E$5:$E$1097,Hoja1!$B$5:$B$1097,B22,Hoja1!$E$5:$E$1097,"<="&H22)),Hoja1!$C$5:$C$1097,""),"")} -> CONST_208_JSA | B22: =IF(LEFT(C22,1)="T","T-","C-")&TRIM(RIGHT(C22,LEN(C22)-SEARCH("-",C22))) -> C-208 | C22: Constituciones-208 | D22: 208 | E22: Sin Dato | F22: S/D | G22: S/D | H22: 38630 | I22: S/D | J22: 38664 | K22: 9 | L22: aceitoso | M22: café claro | N22: Turbio | O22: 1.0056 | P22: 25 | Q22: 0 | R22: 0 | S22: 0 | T22: 6683.7 | U22: 2064.2 | V22: 571.5 | W22: 0.25 | X22: 14861 | Y22: 901.46 | Z22: 325 | AA22: 0 | AB22: 24363.033 | AD22: 0 | AE22: 25407.11 | AF22: 0.357425 | AG22: 7506 | AH22: 797.94 | AK22: 290.60894 | AL22: 103.00358 | AM22: 47.00016 | AN22: 0.00895 | AO22: 419.0802 | AP22: 14.774929 | AQ22: 6.7665 | AR22: 0
A23: {=IFERROR(_xlfn.XLOOKUP(1,(Hoja1!$B$5:$B$1097=B23)*(Hoja1!$E$5:$E$1097=_xlfn.MAXIFS(Hoja1!$E$5:$E$1097,Hoja1!$B$5:$B$1097,B23,Hoja1!$E$5:$E$1097,"<="&H23)),Hoja1!$C$5:$C$1097,""),"")} -> CONST_222_KTIA | B23: =IF(LEFT(C23,1)="T","T-","C-")&TRIM(RIGHT(C23,LEN(C23)-SEARCH("-",C23))) -> C-222 | C23: Constituciones-222 | D23: 222 | E23: Sin Dato | F23: S/D | G23: S/D | H23: 45935 | I23: S/D | J23: 38664 | K23: 9 | L23: fétido | M23: ´transparent | N23: claro | O23: 1.016 | P23: 24 | Q23: 0 | R23: 0 | S23: 0 | T23: 9876.2 | U23: 2825.7 | V23: 814.7 | W23: 0.5 | X23: 21773 | Y23: 540.88 | Z23: 700 | AA23: 0 | AB23: 35329.146 | AD23: 0 | AE23: 36530.98 | AF23: 0.71485 | AG23: 10408 | AH23: 478.76 | AK23: 429.41637 | AL23: 141.00243 | AM23: 67.000928 | AN23: 0.0179 | AO23: 613.9986 | AP23: 8.8650232 | AQ23: 14.574 | AR23: 0
A24: {=IFERROR(_xlfn.XLOOKUP(1,(Hoja1!$B$5:$B$1097=B24)*(Hoja1!$E$5:$E$1097=_xlfn.MAXIFS(Hoja1!$E$5:$E$1097,Hoja1!$B$5:$B$1097,B24,Hoja1!$E$5:$E$1097,"<="&H24)),Hoja1!$C$5:$C$1097,""),"")} -> CONST_223_JSA | B24: =IF(LEFT(C24,1)="T","T-","C-")&TRIM(RIGHT(C24,LEN(C24)-SEARCH("-",C24))) -> C-223 | C24: Constituciones-223 | D24: 223 | E24: Sin Dato | F24: S/D | G24: S/D | H24: 38630 | I24: S/D | J24: 38664 | K24: 9 | L24: Aceitoso | M24: incoloro | N24: claro | O24: 1.0259 | P24: 24 | Q24: 0 | R24: 0 | S24: 69.81 | T24: 11521.2 | U24: 2444.9 | V24: 1045.7 | W24: 1 | X24: 23674 | Y24: 841.37 | Z24: 1325 | AA24: 0 | AB24: 38043.038 | AD24: 5.275 | AE24: 40853.17 | AF24: 1.4297 | AG24: 10408 | AH24: 744.74 | AK24: 500.94868 | AL24: 122.00051 | AM24: 85.998368 | AN24: 0.0358 | AO24: 667.6068 | AP24: 13.790054 | AQ24: 27.5865 | AR24: 0
A25: {=IFERROR(_xlfn.XLOOKUP(1,(Hoja1!$B$5:$B$1097=B25)*(Hoja1!$E$5:$E$1097=_xlfn.MAXIFS(Hoja1!$E$5:$E$1097,Hoja1!$B$5:$B$1097,B25,Hoja1!$E$5:$E$1097,"<="&H25)),Hoja1!$C$5:$C$1097,""),"")} -> CONST_234D_KTIA | B25: =IF(LEFT(C25,1)="T","T-","C-")&TRIM(RIGHT(C25,LEN(C25)-SEARCH("-",C25))) -> C-234D | C25: Constituciones-234D | D25: 234D | E25: Sin Dato | F25: S/D | G25: S/D | H25: 38630 | I25: S/D | J25: 38664 | K25: 9 | L25: Aceitoso | M25: verdoso | N25: Turbio | O25: 1.001 | P25: 24 | Q25: 0 | R25: -63.18 | S25: 64.83 | T25: 7176.4 | U25: 481 | V25: 194.6 | W25: 0.5 | X25: 11750 | Y25: 1262.05 | Z25: 0 | AA25: 0 | AB25: 19351.399 | AD25: 10.549 | AE25: 20864.55 | AF25: 0.71485 | AG25: 2002 | AH25: 1117.11 | AK25: 312.0113 | AL25: 24.0019 | AM25: 16.003904 | AN25: 0.0179 | AO25: 331.35 | AP25: 20.684999 | AQ25: 0 | AR25: 0
A26: {=IFERROR(_xlfn.XLOOKUP(1,(Hoja1!$B$5:$B$1097=B26)*(Hoja1!$E$5:$E$1097=_xlfn.MAXIFS(Hoja1!$E$5:$E$1097,Hoja1!$B$5:$B$1097,B26,Hoja1!$E$5:$E$1097,"<="&H26)),Hoja1!$C$5:$C$1097,""),"")} -> CONST_559_JSA | B26: =IF(LEFT(C26,1)="T","T-","C-")&TRIM(RIGHT(C26,LEN(C26)-SEARCH("-",C26))) -> C-559 | C26: Constituciones-559 | D26: 559 | E26: Sin Dato | F26: S/D | G26: S/D | H26: 38630 | I26: S/D | J26: 38664 | K26: 9 | L26: inodoro | M26: blanco | N26: lig. Turbio | O26: 1.0326 | P26: 25 | Q26: 0 | R26: 0 | S26: 89.76 | T26: 15299.5 | U26: 6613.3 | V26: 1313.2 | W26: 0.25 | X26: 38362 | Y26: 640.63 | Z26: 525 | AA26: 0 | AB26: 61245.995 | AD26: 5.275 | AE26: 62753.88 | AF26: 0.357425 | AG26: 21917 | AH26: 531.96 | AK26: 665.22864 | AL26: 330.00367 | AM26: 107.99757 | AN26: 0.00895 | AO26: 1081.8084 | AP26: 10.499926 | AQ26: 10.9305 | AR26: 0
A27: {=IFERROR(_xlfn.XLOOKUP(1,(Hoja1!$B$5:$B$1097=B27)*(Hoja1!$E$5:$E$1097=_xlfn.MAXIFS(Hoja1!$E$5:$E$1097,Hoja1!$B$5:$B$1097,B27,Hoja1!$E$5:$E$1097,"<="&H27)),Hoja1!$C$5:$C$1097,""),"")} -> CONST_572_KTIA | B27: =IF(LEFT(C27,1)="T","T-","C-")&TRIM(RIGHT(C27,LEN(C27)-SEARCH("-",C27))) -> C-572 | C27: Constituciones-572 | D27: 572 | E27: Sin Dato | F27: S/D | G27: S/D | H27: 38630 | I27: S/D | J27: 38664 | K27: 9 | L27: Aceitoso | M27: verdoso | N27: claro | O27: 1.0106 | P27: 25 | Q27: 0 | R27: 0 | S27: 264.29 | T27: 10984.7 | U27: 1082.2 | V27: 267.5 | W27: 5.75 | X27: 19008 | Y27: 672.67 | Z27: 325 | AA27: 0 | AB27: 31007.425 | AD27: 10.549 | AE27: 32345.82 | AF27: 8.220775 | AG27: 3803 | AH27: 558.56 | AK27: 477.61033 | AL27: 54.00178 | AM27: 21.9992 | AN27: 0.20585 | AO27: 536.0256 | AP27: 11.025061 | AQ27: 6.7665 | AR27: 0
A28: {=IFERROR(_xlfn.XLOOKUP(1,(Hoja1!$B$5:$B$1097=B28)*(Hoja1!$E$5:$E$1097=_xlfn.MAXIFS(Hoja1!$E$5:$E$1097,Hoja1!$B$5:$B$1097,B28,Hoja1!$E$5:$E$1097,"<="&H28)),Hoja1!$C$5:$C$1097,""),"")} -> CONST_589_JSA | B28: =IF(LEFT(C28,1)="T","T-","C-")&TRIM(RIGHT(C28,LEN(C28)-SEARCH("-",C28))) -> C-589 | C28: Constituciones-589 | D28: 589 | E28: Sin Dato | F28: S/D | G28: S/D | H28: 38625 | I28: S/D | J28: 38646 | K28: 8 | L28: fétido | M28: incoloro | N28: transparen | O28: 1.006 | P28: 24 | Q28: 0 | R28: 0 | S28: 39.89 | T28: 3784.8 | U28: 761.5 | V28: 291.8 | W28: 1 | X28: 7585 | Y28: 490.05 | Z28: 225 | AA28: 0 | AB28: 12429.858 | AD28: 10.549 | AE28: 13139.15 | AF28: 1.4297 | AG28: 3102 | AH28: 425.57 | AK28: 164.58114 | AL28: 37.99885 | AM28: 23.997632 | AN28: 0.0358 | AO28: 213.897 | AP28: 8.0319195 | AQ28: 4.6845 | AR28: 0
A29: {=IFERROR(_xlfn.XLOOKUP(1,(Hoja1!$B$5:$B$1097=B29)*(Hoja1!$E$5:$E$1097=_xlfn.MAXIFS(Hoja1!$E$5:$E$1097,Hoja1!$B$5:$B$1097,B29,Hoja1!$E$5:$E$1097,"<="&H29)),Hoja1!$C$5:$C$1097,""),"")} -> CONST_139_JSA | B29: =IF(LEFT(C29,1)="T","T-","C-")&TRIM(RIGHT(C29,LEN(C29)-SEARCH("-",C29))) -> C-139 | C29: Constituciones-139 | D29: 139 | E29: Sin Dato | F29: S/D | G29: S/D | H29: 38625 | I29: S/D | J29: 38655 | K29: 9 | L29: Aceitoso | M29: transparent | N29: Turbio | O29: 1.0119 | P29: 21.5 | Q29: 0 | R29: 34.76 | S29: 119.68 | T29: 7109.8 | U29: 2164.4 | V29: 389.1 | W29: 3.5 | X29: 15169 | Y29: 612.57 | Z29: 550 | AA29: 0 | AB29: 24713.14 | AD29: 10.549 | AE29: 25998.37 | AF29: 5.00395 | AG29: 7005 | AH29: 531.96 | AK29: 309.12838 | AL29: 108.00356 | AM29: 31.999584 | AN29: 0.1253 | AO29: 427.7658 | AP29: 10.040022 | AQ29: 11.451 | AR29: 0
A30: {=IFERROR(_xlfn.XLOOKUP(1,(Hoja1!$B$5:$B$1097=B30)*(Hoja1!$E$5:$E$1097=_xlfn.MAXIFS(Hoja1!$E$5:$E$1097,Hoja1!$B$5:$B$1097,B30,Hoja1!$E$5:$E$1097,"<="&H30)),Hoja1!$C$5:$C$1097,""),"")} -> CONST_174_KTIA | B30: =IF(LEFT(C30,1)="T","T-","C-")&TRIM(RIGHT(C30,LEN(C30)-SEARCH("-",C30))) -> C-174 | C30: Constituciones-174 | D30: 174 | E30: Sin Dato | F30: S/D | G30: S/D | H30: 38629 | I30: S/D | J30: 38646 | K30: 7 | L30: Aceitoso | M30: blanco | N30: Turbio | O30: 1.0056 | P30: 25 | Q30: 0 | R30: 0.34 | S30: 9.97 | T30: 4203.5 | U30: 921.9 | V30: 194.6 | W30: 4.5 | X30: 8274 | Y30: 612.57 | Z30: 75 | AA30: 0 | AB30: 13564.345 | AD30: 10.549 | AE30: 14286.07 | AF30: 6.43365 | AG30: 3102 | AH30: 531.96 | AK30: 182.76051 | AL30: 46.00281 | AM30: 16.003904 | AN30: 0.1611 | AO30: 233.3268 | AP30: 10.040022 | AQ30: 1.5615 | AR30: 0
A31: {=IFERROR(_xlfn.XLOOKUP(1,(Hoja1!$B$5:$B$1097=B31)*(Hoja1!$E$5:$E$1097=_xlfn.MAXIFS(Hoja1!$E$5:$E$1097,Hoja1!$B$5:$B$1097,B31,Hoja1!$E$5:$E$1097,"<="&H31)),Hoja1!$C$5:$C$1097,""),"")} -> CONST_174_KTIA | B31: =IF(LEFT(C31,1)="T","T-","C-")&TRIM(RIGHT(C31,LEN(C31)-SEARCH("-",C31))) -> C-174 | C31: Constituciones-174 | D31: 174 | E31: Sin Dato | F31: S/D | G31: S/D | H31: 38629 | I31: S/D | J31: 38656 | K31: 7 | L31: inodoro | M31: café claro | N31: Turbio | O31: 0.9958 | P31: 24.6 | Q31: 0 | R31: 0 | S31: 119.68 | T31: 4301.1 | U31: 921.9 | V31: 170.2 | W31: 7.75 | X31: 8383 | Y31: 600.98 | Z31: 50 | AA31: 0 | AB31: 13878.289 | AD31: 21.098 | AE31: 14434.93 | AF31: 11.080175 | AG31: 3002 | AH31: 531.96 | AK31: 187.01415 | AL31: 46.00281 | AM31: 13.997248 | AN31: 0.27745 | AO31: 236.4006 | AP31: 9.8500622 | AQ31: 1.041 | AR31: 0
A32: {=IFERROR(_xlfn.XLOOKUP(1,(Hoja1!$B$5:$B$1097=B32)*(Hoja1!$E$5:$E$1097=_xlfn.MAXIFS(Hoja1!$E$5:$E$1097,Hoja1!$B$5:$B$1097,B32,Hoja1!$E$5:$E$1097,"<="&H32)),Hoja1!$C$5:$C$1097,""),"")} | B32: =IF(LEFT(C32,1)="T","T-","C-")&TRIM(RIGHT(C32,LEN(C32)-SEARCH("-",C32))) -> C-195T | C32: Constituciones-195T | D32: 195T | E32: Sin Dato | F32: S/D | G32: S/D | H32: 38629 | I32: S/D | J32: 38656 | K32: 7 | L32: - | M32: verde claro | N32: transparen | O32: 0.9958 | P32: 24.6 | Q32: 0 | R32: 0 | S32: 29.92 | T32: 1285.7 | U32: 240.5 | V32: 73 | W32: 0.75 | X32: 2445 | Y32: 240.39 | Z32: 50 | AA32: 0 | AB32: 4047.7652 | AD32: 10.549 | AE32: 4335.34 | AF32: 1.072275 | AG32: 901 | AH32: 212.78 | AK32: 55.898672 | AL32: 12.00095 | AM32: 6.00352 | AN32: 0.02685 | AO32: 68.949 | AP32: 3.9399921 | AQ32: 1.041 | AR32: 0
A33: {=IFERROR(_xlfn.XLOOKUP(1,(Hoja1!$B$5:$B$1097=B33)*(Hoja1!$E$5:$E$1097=_xlfn.MAXIFS(Hoja1!$E$5:$E$1097,Hoja1!$B$5:$B$1097,B33,Hoja1!$E$5:$E$1097,"<="&H33)),Hoja1!$C$5:$C$1097,""),"")} | B33: =IF(LEFT(C33,1)="T","T-","C-")&TRIM(RIGHT(C33,LEN(C33)-SEARCH("-",C33))) -> C-195T | C33: Constituciones-195T | D33: 195T | E33: Sin Dato | F33: S/D | G33: S/D | H33: 38629 | I33: S/D | J33: 38646 | K33: 7 | L33: Aceitoso | M33: café | N33: Turbio | O33: 1.0056 | P33: 25 | Q33: 0 | R33: 0.34 | S33: 59.84 | T33: 3005.2 | U33: 601.2 | V33: 145.9 | W33: 7.5 | X33: 5861 | Y33: 245.03 | Z33: 175 | AA33: 0 | AB33: 9608.4876 | AD33: 5.275 | AE33: 10040.83 | AF33: 10.72275 | AG33: 2102 | AH33: 212.78 | AK33: 130.67255 | AL33: 29.99988 | AM33: 11.998816 | AN33: 0.2685 | AO33: 165.2802 | AP33: 4.0160417 | AQ33: 3.6435 | AR33: 0
A34: {=IFERROR(_xlfn.XLOOKUP(1,(Hoja1!$B$5:$B$1097=B34)*(Hoja1!$E$5:$E$1097=_xlfn.MAXIFS(Hoja1!$E$5:$E$1097,Hoja1!$B$5:$B$1097,B34,Hoja1!$E$5:$E$1097,"<="&H34)),Hoja1!$C$5:$C$1097,""),"")} -> CONST_199_JSA | B34: =IF(LEFT(C34,1)="T","T-","C-")&TRIM(RIGHT(C34,LEN(C34)-SEARCH("-",C34))) -> C-199 | C34: Constituciones-199 | D34: 199 | E34: Sin Dato | F34: S/D | G34: S/D | H34: 38629 | I34: S/D | J34: 38646 | K34: 9 | L34: fétido | M34: incoloro | N34: transparen | O34: 1.0063 | P34: 23 | Q34: 0 | R34: 0.34 | S34: 59.84 | T34: 5511.4 | U34: 1202.4 | V34: 267.5 | W34: 0.75 | X34: 11032 | Y34: 612.57 | Z34: 25 | AA34: 0 | AB34: 18073.213 | AD34: 5.275 | AE34: 18651.62 | AF34: 1.072275 | AG34: 4103 | AH34: 531.96 | AK34: 239.63711 | AL34: 59.99976 | AM34: 21.9992 | AN34: 0.02685 | AO34: 311.1024 | AP34: 10.040022 | AQ34: 0.5205 | AR34: 0
A35: {=IFERROR(_xlfn.XLOOKUP(1,(Hoja1!$B$5:$B$1097=B35)*(Hoja1!$E$5:$E$1097=_xlfn.MAXIFS(Hoja1!$E$5:$E$1097,Hoja1!$B$5:$B$1097,B35,Hoja1!$E$5:$E$1097,"<="&H35)),Hoja1!$C$5:$C$1097,""),"")} -> CONST_199_JSA | B35: =IF(LEFT(C35,1)="T","T-","C-")&TRIM(RIGHT(C35,LEN(C35)-SEARCH("-",C35))) -> C-199 | C35: Constituciones-199 | D35: 199 | E35: Sin Dato | F35: S/D | G35: S/D | H35: 38629 | I35: S/D | J35: 38656 | K35: 6 | L35: a tierra | M35: café claro | N35: Turbio | O35: 0.9958 | P35: 24.6 | Q35: 0 | R35: 0 | S35: 19.95 | T35: 1414.8 | U35: 280.6 | V35: 24.3 | W35: 3.25 | X35: 2445 | Y35: 180.29 | Z35: 275 | AA35: 0 | AB35: 4047.7652 | AD35: 10.549 | AE35: 4623.24 | AF35: 4.646525 | AG35: 801 | AH35: 159.59 | AK35: 61.512731 | AL35: 14.00194 | AM35: 1.998432 | AN35: 0.11635 | AO35: 68.949 | AP35: 2.9549531 | AQ35: 5.7255 | AR35: 0
A36: {=IFERROR(_xlfn.XLOOKUP(1,(Hoja1!$B$5:$B$1097=B36)*(Hoja1!$E$5:$E$1097=_xlfn.MAXIFS(Hoja1!$E$5:$E$1097,Hoja1!$B$5:$B$1097,B36,Hoja1!$E$5:$E$1097,"<="&H36)),Hoja1!$C$5:$C$1097,""),"")} -> CONST_200_JSA | B36: =IF(LEFT(C36,1)="T","T-","C-")&TRIM(RIGHT(C36,LEN(C36)-SEARCH("-",C36))) -> C-200 | C36: Constituciones-200 | D36: 200 | E36: Sin Dato | F36: S/D | G36: S/D | H36: 38625 | I36: S/D | J36: 38645 | K36: 9 | L36: Aceitoso | M36: café claro | N36: Turbio | O36: 1.0019 | P36: 21.5 | Q36: 0 | R36: 103.61 | S36: 29.92 | T36: 4431.3 | U36: 961.9 | V36: 145.9 | W36: 1.75 | X36: 8274 | Y36: 612.57 | Z36: 450 | AA36: 0 | AB36: 13614.438 | AD36: 5.275 | AE36: 14877.42 | AF36: 2.501975 | AG36: 3002 | AH36: 531.96 | AK36: 192.67555 | AL36: 47.99881 | AM36: 11.998816 | AN36: 0.06265 | AO36: 233.3268 | AP36: 10.040022 | AQ36: 9.369 | AR36: 0
A37: {=IFERROR(_xlfn.XLOOKUP(1,(Hoja1!$B$5:$B$1097=B37)*(Hoja1!$E$5:$E$1097=_xlfn.MAXIFS(Hoja1!$E$5:$E$1097,Hoja1!$B$5:$B$1097,B37,Hoja1!$E$5:$E$1097,"<="&H37)),Hoja1!$C$5:$C$1097,""),"")} -> CONST_202_JSA | B37: =IF(LEFT(C37,1)="T","T-","C-")&TRIM(RIGHT(C37,LEN(C37)-SEARCH("-",C37))) -> C-202 | C37: Constituciones-202 | D37: 202 | E37: Sin Dato | F37: S/D | G37: S/D | H37: 38625 | I37: S/D | J37: 38646 | K37: 9 | L37: Aceitoso | M37: blanco | N37: Turbio | O37: 1.0202 | P37: 26 | Q37: 0 | R37: 0.34 | S37: 29.92 | T37: 9015.2 | U37: 1442.9 | V37: 656.6 | W37: 0.5 | X37: 17238 | Y37: 612.57 | Z37: 1050 | AA37: 0 | AB37: 27855.447 | AD37: 0 | AE37: 30015.77 | AF37: 0.71485 | AG37: 6305 | AH37: 531.96 | AK37: 391.99523 | AL37: 72.00071 | AM37: 53.998784 | AN37: 0.0179 | AO37: 486.1116 | AP37: 10.040022 | AQ37: 21.861 | AR37: 0
A38: {=IFERROR(_xlfn.XLOOKUP(1,(Hoja1!$B$5:$B$1097=B38)*(Hoja1!$E$5:$E$1097=_xlfn.MAXIFS(Hoja1!$E$5:$E$1097,Hoja1!$B$5:$B$1097,B38,Hoja1!$E$5:$E$1097,"<="&H38)),Hoja1!$C$5:$C$1097,""),"")} -> CONST_203_JSA | B38: =IF(LEFT(C38,1)="T","T-","C-")&TRIM(RIGHT(C38,LEN(C38)-SEARCH("-",C38))) -> C-203 | C38: Constituciones-203 | D38: 203 | E38: Sin Dato | F38: S/D | G38: S/D | H38: 38625 | I38: S/D | J38: 38645 | K38: 9 | L38: fétido | M38: café claro | N38: Turbio | O38: 1.0019 | P38: 21.5 | Q38: 0 | R38: 103.61 | S38: 29.92 | T38: 4049.6 | U38: 1122.3 | V38: 413.4 | W38: 0.75 | X38: 8619 | Y38: 612.57 | Z38: 625 | AA38: 0 | AB38: 14182.118 | AD38: 5.275 | AE38: 15442.62 | AF38: 1.072275 | AG38: 4503 | AH38: 531.96 | AK38: 176.08069 | AL38: 56.00277 | AM38: 33.998016 | AN38: 0.02685 | AO38: 243.0558 | AP38: 10.040022 | AQ38: 13.0125 | AR38: 0
A39: {=IFERROR(_xlfn.XLOOKUP(1,(Hoja1!$B$5:$B$1097=B39)*(Hoja1!$E$5:$E$1097=_xlfn.MAXIFS(Hoja1!$E$5:$E$1097,Hoja1!$B$5:$B$1097,B39,Hoja1!$E$5:$E$1097,"<="&H39)),Hoja1!$C$5:$C$1097,""),"")} -> CONST_209D_KTIA | B39: =IF(LEFT(C39,1)="T","T-","C-")&TRIM(RIGHT(C39,LEN(C39)-SEARCH("-",C39))) -> C-209D | C39: Constituciones-209D | D39: 209D | E39: Sin Dato | F39: S/D | G39: S/D | H39: 38625 | I39: S/D | J39: 38645 | K39: 9 | L39: inodoro | M39: transparent | N39: lig turbio | O39: 1.0218 | P39: 21.5 | Q39: 0 | R39: 34.76 | S39: 0 | T39: 15403.6 | U39: 961.9 | V39: 437.7 | W39: 0.5 | X39: 258.56 | Y39: 1286.39 | Z39: 25 | AA39: 90.36 | AB39: 417.1613 | AD39: 0 | AE39: 18464.01 | AF39: 0.71485 | AG39: 4203 | AH39: 1117.11 | AK39: -52.105635 | AL39: 47.99881 | AM39: 35.996448 | AN39: 0.0179 | AO39: 7.291392 | AP39: 21.083932 | AQ39: 0.5205 | AR39: 3.0116988
A40: {=IFERROR(_xlfn.XLOOKUP(1,(Hoja1!$B$5:$B$1097=B40)*(Hoja1!$E$5:$E$1097=_xlfn.MAXIFS(Hoja1!$E$5:$E$1097,Hoja1!$B$5:$B$1097,B40,Hoja1!$E$5:$E$1097,"<="&H40)),Hoja1!$C$5:$C$1097,""),"")} -> CONST_221_JSA | B40: =IF(LEFT(C40,1)="T","T-","C-")&TRIM(RIGHT(C40,LEN(C40)-SEARCH("-",C40))) -> C-221 | C40: Constituciones-221 | D40: 221 | E40: Sin Dato | F40: S/D | G40: S/D | H40: 38629 | I40: S/D | J40: 38646 | K40: 9 | L40: aceitoso | M40: café verdoso | N40: turbio | O40: 1.0023 | P40: 23 | Q40: 0 | R40: 0.34 | S40: 29.92 | T40: 6182.2 | U40: 1162.3 | V40: 291.08 | W40: 0.75 | X40: 12066 | Y40: 612.57 | Z40: 25 | AA40: 0 | AB40: 19846.054 | AD40: 5.275 | AE40: 20339.9 | AF40: 1.072275 | AG40: 4103 | AH40: 531.96 | AK40: 268.85768 | AL40: 57.99877 | AM40: 23.938419 | AN40: 0.02685 | AO40: 340.2612 | AP40: 10.040022 | AQ40: 0.5205 | AR40: 0
...

Sheet Hoja1
B3: Pozo | C3: TERMINACION | D3: Yacimiento | E3: Fecha
B4: CH-1001 | C4: CHAMPAYAN_1001_KTIA | D4: KTIA | E4: 35521
B5: CH-1004 | C5: CHAMPAYAN_1004_KTIA | D5: KTIA | E5: 35521
B6: CH-1005 | C6: CHAMPAYAN_1005_KTIA | D6: KTIA | E6: 33817
B7: CH-1006 | C7: CHAMPAYAN_1006_KTIA | D7: KTIA | E7: 34335
B8: C-101 | C8: CONST_101_JAR | D8: JAR | E8: 21002
B9: C-101 | C9: CONST_101_KTIA | D9: KTIA | E9: 27760
B10: C-102 | C10: CONST_102_JSA | D10: JSA | E10: 20790
B11: C-102 | C11: CONST_102_KTIA | D11: KTIA | E11: 35765
B12: C-103 | C12: CONST_103_JSA | D12: JSA | E12: 21125
B13: C-103 | C13: CONST_103_KTIA | D13: KTIA | E13: 30956
B14: C-104 | C14: CONST_104_JSA | D14: JSA | E14: 21064
B15: C-105 | C15: CONST_105_JSA | D15: JSA | E15: 21367
... B1096: T-19 | C1096: TMLP_19_KTIA | D1096: KTIA | E1096: 20852
